Workbook

Sheet Shopping List
A1: Category | B1: Item | C1: When | D1: Pack / size | E1: # to buy | F1: Price each | G1: Line total | H1: Status | I1: Amazon product | J1: Link | K1: Rating | L1: Ratings count | M1: What it is | N1: Tip | O1: Our notes
A2: Travel | B2: Car seat + stroller (travel system) | C2: Before birth | D2: 1 | E2: 1 | F2: 143.99 | G2: =IF(F2="","",E2*F2) -> 143.99 | H2: Idea | I2: Baby Trend EZ Ride Travel System with EZ-Lift Infant Car Seat, Dash Grey | J2: Open | K2: 4.6 | L2: 1500 | M2: Infant car seat that clicks into a matching stroller. The one thing the hospital requires before you leave. | N2: Budget pick. Install it by week 36 and get a free car seat check.
A3: Travel | B3: Upgrade: Chicco KeyFit 35 car seat | C3: Optional | D3: 1 | E3: 1 | F3: 209.99 | G3: =IF(F3="","",E3*F3) -> 209.99 | H3: Idea | I3: Chicco KeyFit 35 Infant Car Seat (check the listing says KeyFit 35) | J3: Open | K3: 4.8 | L3: 890 | M3: A top-rated infant car seat with easy, very secure installation. Lasts longer (up to 35 lb). | N3: Only if you skip the travel system. Pair with a Chicco-compatible stroller.
A4: Travel | B4: Back-seat mirror | C4: Before birth | D4: 1 | E4: 1 | F4: 17.59 | G4: =IF(F4="","",E4*F4) -> 17.59 | H4: Idea | I4: Shynerk Baby Car Mirror, Safety Car Seat Mirror for Rear Facing Infant with Wide Crystal Clear View, Shatterpr | J4: Open | K4: 4.7 | L4: 31432 | M4: Lets you see the rear-facing baby from the driver seat.
A5: Travel | B5: Car window sun shades | C5: Before birth | D5: 2-pack | E5: 1 | F5: 11.99 | G5: =IF(F5="","",E5*F5) -> 11.99 | H5: Idea | I5: Munchkin Brica Sun Safety Car Window Shade for Baby, 2 Pack, Black | J5: Open | K5: 4.3 | L5: 13836 | M5: Cling-on shades for the back side windows. A must for Arizona sun.
A6: Travel | B6: Diaper bag backpack | C6: Before birth | D6: 1 | E6: 1 | F6: 60.99 | G6: =IF(F6="","",E6*F6) -> 60.99 | H6: Idea | I6: BabbleRoo Extra Large Diaper Bag Backpack, Expandable Baby Bag with Up to 50% More Capacity - Travel Essential | J6: Open | K6: 4.8 | L6: 12831 | M6: Big backpack-style bag with insulated bottle pockets and a changing pad. | N6: Cheaper option: Tenot diaper backpack, about $19.
A7: Travel | B7: Baby carrier | C7: First weeks | D7: 1 | E7: 1 | F7: 28.89 | G7: =IF(F7="","",E7*F7) -> 28.89 | H7: Idea | I7: Infantino Flip 4-in-1 Baby Carrier Convertible Ergonomic, Gray | J7: Open | K7: 4.6 | L7: 83603 | M7: Soft structured carrier, front or back, from about 8 lb. Hands-free errands and fussy evenings.
A8: Travel | B8: Stretchy newborn wrap | C8: Optional | D8: 1 | E8: 1 | F8: 39.99 | G8: =IF(F8="","",E8*F8) -> 39.99 | H8: Idea | I8: Boba Baby Wrap Carrier - Stretch Cotton Newborn Sling, Gray | J8: Open | K8: 4.6 | L8: 28838 | M8: Soft fabric wrap that newborns love for the first 3 months. | N8: Nice extra; the carrier above covers most needs.
A9: Sleep | B9: Pack ’n Play with bassinet | C9: Before birth | D9: 1 | E9: 1 | F9: 199.99 | G9: =IF(F9="","",E9*F9) -> 199.99 | H9: Idea | I9: Graco Close2Baby Pack 'n Play Playard, Derby | J9: Open | K9: 4.8 | L9: 2595 | M9: Bedside bassinet for the first months, then a playard. Doubles as the travel crib. | N9: Means you can wait on the crib until the baby is 4–6 months old.
A10: Sleep | B10: Pack ’n Play fitted sheets | C10: Before birth | D10: 2-pack × 2 | E10: 2 | F10: 9.99 | G10: =IF(F10="","",E10*F10) -> 19.98 | H10: Idea | I10: Yoofoss 2-Pack Pack and Play Sheets Fitted 38x26 (Green+Giraffe) | J10: Open | K10: 4.9 | L10: 3426 | M10: Fitted sheets sized 38×26" for the playard mattress. Blowouts happen at night, so have spares.
A11: Sleep | B11: Swaddle sleep sacks | C11: Before birth | D11: 2 | E11: 2 | F11: 34.95 | G11: =IF(F11="","",E11*F11) -> 69.9 | H11: Idea | I11: HALO SleepSack Swaddle | Cotton | 1.5 TOG | 68-75°F | 6-12 lbs |Cream | J11: Open | K11: 4.6 | L11: 24970 | M11: Wearable swaddle with Velcro wings. Easier and safer than wrapping a blanket. | N11: Newborn size fits 6–12 lb.
A12: Sleep | B12: Muslin swaddle blankets | C12: First weeks | D12: 4-pack | E12: 1 | F12: 39.95 | G12: =IF(F12="","",E12*F12) -> 39.95 | H12: Idea | I12: aden + anais Swaddle Blanket, Boutique Muslin Blankets for Girls & Boys, Baby Receiving Swaddles, Ideal Newbor | J12: Open | K12: 4.8 | L12: 6349 | M12: Light, breathable blankets for swaddling, nursing cover, stroller shade and burp cloth.
A13: Sleep | B13: Sound machine + night light | C13: First weeks | D13: 1 | E13: 1 | F13: 79.99 | G13: =IF(F13="","",E13*F13) -> 79.99 | H13: Idea | I13: Hatch Baby Sound Machine & Night Light Routine Builder (Mint) | J13: Open | K13: 4.7 | L13: 36538 | M13: White noise plus a dim night light for feeds, controlled from your phone.
A14: Sleep | B14: Baby monitor | C14: Optional | D14: 1 | E14: 0 | F14: 44.97 | G14: =IF(F14="","",E14*F14) -> 0 | H14: Idea | I14: WYZE Cam v4 (Latest Model), 2.5K AI Security Camera, Indoor/Outdoor Cameras for Home Security, Baby Monitor & | J14: Open | K14: 4.3 | L14: 11426 | M14: Video monitor with night vision and alerts on your phone. | N14: You already own Wyze cams. Reuse one and spend $0.
A15: Sleep | B15: Sleep sacks (wearable blanket) | C15: Later (2+ months) | D15: 2 | E15: 2 | F15: 34.95 | G15: =IF(F15="","",E15*F15) -> 69.9 | H15: Idea | I15: HALO SleepSack, 100% Cotton Wearable Blanket, Swaddle Transition Sleeping Bag, TOG 0.5 | J15: Open | K15: 4.8 | L15: 23503 | M15: Replaces blankets once baby is out of the swaddle, around 3–4 months.
A16: Sleep | B16: Convertible crib | C16: Later (2+ months) | D16: 1 | E16: 1 | F16: 176.52 | G16: =IF(F16="","",E16*F16) -> 176.52 | H16: Idea | I16: Delta Children Essex 4-in-1 Convertible Baby Crib, Bianca White with Natural Legs | J16: Open | K16: 4.7 | L16: 4512 | M16: Converts to toddler bed, daybed and full-size bed. | N16: Buy when the baby moves out of the bassinet.
A17: Sleep | B17: Crib mattress | C17: Later (2+ months) | D17: 1 | E17: 1 | F17: 52 | G17: =IF(F17="","",E17*F17) -> 52 | H17: Idea | I17: Dream On Me 2-in-1 Serene Snooze Baby Crib Mattress, GREENGUARD Gold | J17: Open | K17: 4.6 | L17: 8822 | M17: Firm, GREENGUARD Gold certified, with an infant side and a toddler side. | N17: Always buy new. Newton Essential (~$200) is a breathable, washable upgrade.
A18: Feeding | B18: Breast pump (through insurance) | C18: Before birth | D18: 1 | E18: 1 | F18: 0 | G18: =IF(F18="","",E18*F18) -> 0 | H18: Idea | I18: Electric pump covered by health insurance (e.g., via Aeroflow) | J18: Open | M18: Most insurance plans must cover an electric breast pump at no cost. | N18: Request it in December; it ships before the due date.
A19: Feeding | B19: Bottles (4 oz) | C19: Before birth | D19: 4-pack | E19: 1 | F19: 24.49 | G19: =IF(F19="","",E19*F19) -> 24.49 | H19: Idea | I19: Dr. Brown's Anti-Colic Options+ Narrow Baby Bottle, Clear, 4 oz, 4-Pack | J19: Open | K19: 4.7 | L19: 53509 | M19: Anti-colic newborn bottles. Even breastfed babies often get some bottles. | N19: Start with one pack and see what your baby likes.
A20: Feeding | B20: Bottle brush | C20: Before birth | D20: 1 | E20: 1 | F20: 9.99 | G20: =IF(F20="","",E20*F20) -> 9.99 | H20: Idea | I20: OXO Tot Baby Bottle Brush with Nipple Cleaner, Baby Bottle Cleaner, Blossom | J20: Open | K20: 4.8 | L20: 37210 | M20: Brush with a built-in nipple cleaner.
A21: Feeding | B21: Bottle drying rack | C21: First weeks | D21: 1 | E21: 1 | F21: 21.99 | G21: =IF(F21="","",E21*F21) -> 21.99 | H21: Idea | I21: Boon Lawn Countertop Baby Bottle Drying Rack - Spring Green - 13.5x11x2.5 | J21: Open | K21: 4.8 | L21: 13942 | M21: Countertop rack for bottles, pump parts and pacifiers.
A22: Feeding | B22: Burp cloths | C22: Before birth | D22: 10-pack | E22: 1 | F22: 19.99 | G22: =IF(F22="","",E22*F22) -> 19.99 | H22: Idea | I22: Comfy Cubs Muslin Burp Cloths 20x10" 10 Pack, Baby Burp Cloths - Multi | J22: Open | K22: 4.8 | L22: 41137 | M22: Absorbent muslin cloths. You will use these constantly.
A23: Feeding | B23: Nursing pillow | C23: First weeks | D23: 1 | E23: 1 | F23: 22.99 | G23: =IF(F23="","",E23*F23) -> 22.99 | H23: Idea | I23: Nursing Pillow and Positioner, Breastfeeding, Bottle Feeding | J23: Open | K23: 4.6 | L23: 1352 | M23: Props the baby up for feeding so your arms and back don’t do all the work. | N23: The Boppy original is about $50 if you prefer the name brand.
A24: Feeding | B24: Nipple cream | C24: Before birth | D24: 1 | E24: 1 | F24: 9.49 | G24: =IF(F24="","",E24*F24) -> 9.49 | H24: Idea | I24: Lansinoh Lanolin Nipple Cream, 1.41 Ounces | J24: Open | K24: 4.8 | L24: 54940 | M24: Soothes sore nipples in the first weeks of breastfeeding.
A25: Feeding | B25: Nursing pads | C25: First weeks | D25: 100 ct | E25: 1 | F25: 11.49 | G25: =IF(F25="","",E25*F25) -> 11.49 | H25: Idea | I25: Lansinoh Stay Dry Disposable Nursing Pads, 100 Count | J25: Open | K25: 4.8 | L25: 53256 | M25: Disposable pads that catch leaks.
A26: Feeding | B26: Milk storage bags | C26: First weeks | D26: 50 ct | E26: 1 | F26: 9.34 | G26: =IF(F26="","",E26*F26) -> 9.34 | H26: Idea | I26: Lansinoh Breastmilk Storage Bags, 6 Ounce, 50 Count | J26: Open | K26: 4.8 | L26: 94920 | M26: Freezer bags for pumped milk.
A27: Feeding | B27: Silicone milk catcher | C27: First weeks | D27: 1 | E27: 1 | F27: 12.94 | G27: =IF(F27="","",E27*F27) -> 12.94 | H27: Idea | I27: haakaa Manual Breast Pump for Breastfeeding 4oz/100ml | J27: Open | K27: 4.6 | L27: 96218 | M27: Collects let-down milk from the other side while nursing.
A28: Feeding | B28: Pacifiers | C28: First weeks | D28: 4-pack | E28: 1 | F28: 9.51 | G28: =IF(F28="","",E28*F28) -> 9.51 | H28: Idea | I28: Philips Avent Soothie Baby Pacifier for 0-3 Months, BPA-Free, 4-Pack, Green | J28: Open | K28: 4.8 | L28: 21527 | M28: The hospital-standard newborn pacifier.
A29: Diapering | B29: Newborn diapers | C29: Before birth | D29: 84 ct | E29: 1 | F29: 27.97 | G29: =IF(F29="","",E29*F29) -> 27.97 | H29: Idea | I29: Pampers Swaddlers Diapers, Size 0 (up to 10 lbs), 84 Count, Fragrance Free, Hypoallergenic, Absorbent, Pediatr | J29: Open | K29: 4.8 | L29: 129117 | M29: Size 0, up to 10 lb. | N29: Buy one box only; most babies outgrow this size in weeks.
A30: Diapering | B30: Size 1 diapers | C30: Before birth | D30: 198 ct | E30: 1 | F30: 49.77 | G30: =IF(F30="","",E30*F30) -> 49.77 | H30: Idea | I30: Pampers Swaddlers Diapers, Size 1 (8-14 lbs), 198 Count, Fragrance Free, Hypoallergenic, Absorbent, Pediatrici | J30: Open | K30: 4.8 | L30: 129117 | M30: Size 1, 8–14 lb. This is the size you’ll use most at first.
A31: Diapering | B31: Wipes | C31: Before birth | D31: 720 ct | E31: 1 | F31: 44.97 | G31: =IF(F31="","",E31*F31) -> 44.97 | H31: Idea | I31: WaterWipes Sensitive+ Newborn & Baby Wipes, 3-In-1 Cleans, Cares, Protects, 99.9% Water, Unscented & Hypoaller | J31: Open | K31: 4.7 | L31: 88181 | M31: Gentle, unscented wipes, mostly water.
A32: Diapering | B32: Healing ointment | C32: Before birth | D32: 7 oz | E32: 1 | F32: 12.97 | G32: =IF(F32="","",E32*F32) -> 12.97 | H32: Idea | I32: Aquaphor Baby Advanced Therapy Healing Ointment Skin Protectant, 7 OZ | J32: Open | K32: 4.9 | L32: 91980 | M32: Barrier ointment for diaper area and dry skin.
A33: Diapering | B33: Diaper rash cream | C33: First weeks | D33: 4.8 oz | E33: 1 | F33: 7.97 | G33: =IF(F33="","",E33*F33) -> 7.97 | H33: Idea | I33: Desitin Maximum Strength Diaper Rash Paste, 40% Zinc Oxide, 4.8 oz | J33: Open | K33: 4.8 | L33: 51948 | M33: Thick zinc paste for when a rash does show up.
A34: Diapering | B34: Changing pad | C34: Before birth | D34: 1 | E34: 1 | F34: 19 | G34: =IF(F34="","",E34*F34) -> 19 | H34: Idea | I34: Serta Foam Contoured Changing Pad with Waterproof Cover | J34: Open | K34: 4.5 | L34: 2027 | M34: Contoured foam pad with waterproof cover. Works on a dresser top.
A35: Diapering | B35: Changing pad covers | C35: Before birth | D35: 2-pack | E35: 1 | F35: 9.99 | G35: =IF(F35="","",E35*F35) -> 9.99 | H35: Idea | I35: Changing Pad Cover for Boys Girls, Soft Unisex Diaper Change Table Sheets | J35: Open | K35: 4.7 | L35: 3042 | M35: Washable covers so you can swap after messes.
A36: Diapering | B36: Diaper pail | C36: Optional | D36: 1 | E36: 1 | F36: 69.99 | G36: =IF(F36="","",E36*F36) -> 69.99 | H36: Idea | I36: Ubbi Stainless Steel Diaper Pail, No Special Bags, Odor-Locking, White | J36: Open | K36: 4.6 | L36: 10049 | M36: Odor-sealing steel pail that takes regular trash bags. | N36: A small lidded trash can works too.
A37: Clothing | B37: Zip sleepers, 0–3 months | C37: Before birth | D37: 3-pack × 2 | E37: 2 | F37: 25 | G37: =IF(F37="","",E37*F37) -> 50 | H37: Idea | I37: Simple Joys by Carter's Baby 3-Pack Neutral Sleep and Play | J37: Open | K37: 4.8 | L37: 29399 | M37: Zip footie pajamas. Babies basically live in these. | N37: Zippers beat snaps at 3 a.m.
A38: Clothing | B38: Sleepers, newborn size | C38: Before birth | D38: 4-pack | E38: 1 | F38: 23.99 | G38: =IF(F38="","",E38*F38) -> 23.99 | H38: Idea | I38: Gerber Baby Girls 4-Pack Sleep 'N Play Footie | J38: Open | K38: 4.7 | L38: 72826 | M38: A few newborn-size sleepers for the first weeks. | N38: Choose the color set you like on the listing.
A39: Clothing | B39: Bodysuits | C39: Before birth | D39: 5-pack × 2 | E39: 2 | F39: 11.66 | G39: =IF(F39="","",E39*F39) -> 23.32 | H39: Idea | I39: Gerber Baby Boys & Girls 5-Pack Solid Onesies Bodysuits | J39: Open | K39: 4.8 | L39: 58485 | M39: Short-sleeve onesies for layering. Get 0–3 months.
A40: Clothing | B40: Socks | C40: Before birth | D40: 6-pack | E40: 1 | F40: 10.95 | G40: =IF(F40="","",E40*F40) -> 10.95 | H40: Idea | I40: Gerber Baby Boys & Girls 6-Pack White Terry Socks | J40: Open | K40: 4.4 | L40: 15198 | M40: Terry socks for outings and cool February nights.
...

Sheet Summary
A1: Baby Arrival List
A2: Due February 2027. Totals update as you change Status and # to buy on the Shopping List tab.
A4: When | B4: Still to buy | C4: Marked Want | D4: Already got | E4: Items
A5: Before birth | B5: =SUMIFS('Shopping List'!$G$2:$G$64,'Shopping List'!$C$2:$C$64,$A5,'Shopping List'!$H$2:$H$64,"<>Skip",'Shopping List'!$H$2:$H$64,"<>Got") -> 1004.81 | C5: =SUMIFS('Shopping List'!$G$2:$G$64,'Shopping List'!$C$2:$C$64,$A5,'Shopping List'!$H$2:$H$64,"Want") -> 0 | D5: =SUMIFS('Shopping List'!$G$2:$G$64,'Shopping List'!$C$2:$C$64,$A5,'Shopping List'!$H$2:$H$64,"Got") -> 0 | E5: =COUNTIFS('Shopping List'!$C$2:$C$64,$A5) -> 36
A6: First weeks | B6: =SUMIFS('Shopping List'!$G$2:$G$64,'Shopping List'!$C$2:$C$64,$A6,'Shopping List'!$H$2:$H$64,"<>Skip",'Shopping List'!$H$2:$H$64,"<>Got") -> 418.86 | C6: =SUMIFS('Shopping List'!$G$2:$G$64,'Shopping List'!$C$2:$C$64,$A6,'Shopping List'!$H$2:$H$64,"Want") -> 0 | D6: =SUMIFS('Shopping List'!$G$2:$G$64,'Shopping List'!$C$2:$C$64,$A6,'Shopping List'!$H$2:$H$64,"Got") -> 0 | E6: =COUNTIFS('Shopping List'!$C$2:$C$64,$A6) -> 18
A7: Later (2+ months) | B7: =SUMIFS('Shopping List'!$G$2:$G$64,'Shopping List'!$C$2:$C$64,$A7,'Shopping List'!$H$2:$H$64,"<>Skip",'Shopping List'!$H$2:$H$64,"<>Got") -> 341.39 | C7: =SUMIFS('Shopping List'!$G$2:$G$64,'Shopping List'!$C$2:$C$64,$A7,'Shopping List'!$H$2:$H$64,"Want") -> 0 | D7: =SUMIFS('Shopping List'!$G$2:$G$64,'Shopping List'!$C$2:$C$64,$A7,'Shopping List'!$H$2:$H$64,"Got") -> 0 | E7: =COUNTIFS('Shopping List'!$C$2:$C$64,$A7) -> 4
A8: Optional | B8: =SUMIFS('Shopping List'!$G$2:$G$64,'Shopping List'!$C$2:$C$64,$A8,'Shopping List'!$H$2:$H$64,"<>Skip",'Shopping List'!$H$2:$H$64,"<>Got") -> 331.16 | C8: =SUMIFS('Shopping List'!$G$2:$G$64,'Shopping List'!$C$2:$C$64,$A8,'Shopping List'!$H$2:$H$64,"Want") -> 0 | D8: =SUMIFS('Shopping List'!$G$2:$G$64,'Shopping List'!$C$2:$C$64,$A8,'Shopping List'!$H$2:$H$64,"Got") -> 0 | E8: =COUNTIFS('Shopping List'!$C$2:$C$64,$A8) -> 5
A9: Total | B9: =SUM(B5:B8) -> 2096.22 | C9: =SUM(C5:C8) -> 0 | D9: =SUM(D5:D8) -> 0 | E9: =SUM(E5:E8) -> 63
A11: Category | B11: Still to buy | C11: Marked Want | D11: Already got | E11: Items
A12: Travel | B12: =SUMIFS('Shopping List'!$G$2:$G$64,'Shopping List'!$A$2:$A$64,$A12,'Shopping List'!$H$2:$H$64,"<>Skip",'Shopping List'!$H$2:$H$64,"<>Got") -> 513.43 | C12: =SUMIFS('Shopping List'!$G$2:$G$64,'Shopping List'!$A$2:$A$64,$A12,'Shopping List'!$H$2:$H$64,"Want") -> 0 | D12: =SUMIFS('Shopping List'!$G$2:$G$64,'Shopping List'!$A$2:$A$64,$A12,'Shopping List'!$H$2:$H$64,"Got") -> 0 | E12: =COUNTIFS('Shopping List'!$A$2:$A$64,$A12) -> 7
A13: Sleep | B13: =SUMIFS('Shopping List'!$G$2:$G$64,'Shopping List'!$A$2:$A$64,$A13,'Shopping List'!$H$2:$H$64,"<>Skip",'Shopping List'!$H$2:$H$64,"<>Got") -> 708.23 | C13: =SUMIFS('Shopping List'!$G$2:$G$64,'Shopping List'!$A$2:$A$64,$A13,'Shopping List'!$H$2:$H$64,"Want") -> 0 | D13: =SUMIFS('Shopping List'!$G$2:$G$64,'Shopping List'!$A$2:$A$64,$A13,'Shopping List'!$H$2:$H$64,"Got") -> 0 | E13: =COUNTIFS('Shopping List'!$A$2:$A$64,$A13) -> 9
A14: Feeding | B14: =SUMIFS('Shopping List'!$G$2:$G$64,'Shopping List'!$A$2:$A$64,$A14,'Shopping List'!$H$2:$H$64,"<>Skip",'Shopping List'!$H$2:$H$64,"<>Got") -> 152.22 | C14: =SUMIFS('Shopping List'!$G$2:$G$64,'Shopping List'!$A$2:$A$64,$A14,'Shopping List'!$H$2:$H$64,"Want") -> 0 | D14: =SUMIFS('Shopping List'!$G$2:$G$64,'Shopping List'!$A$2:$A$64,$A14,'Shopping List'!$H$2:$H$64,"Got") -> 0 | E14: =COUNTIFS('Shopping List'!$A$2:$A$64,$A14) -> 11
A15: Diapering | B15: =SUMIFS('Shopping List'!$G$2:$G$64,'Shopping List'!$A$2:$A$64,$A15,'Shopping List'!$H$2:$H$64,"<>Skip",'Shopping List'!$H$2:$H$64,"<>Got") -> 242.63 | C15: =SUMIFS('Shopping List'!$G$2:$G$64,'Shopping List'!$A$2:$A$64,$A15,'Shopping List'!$H$2:$H$64,"Want") -> 0 | D15: =SUMIFS('Shopping List'!$G$2:$G$64,'Shopping List'!$A$2:$A$64,$A15,'Shopping List'!$H$2:$H$64,"Got") -> 0 | E15: =COUNTIFS('Shopping List'!$A$2:$A$64,$A15) -> 8
A16: Clothing | B16: =SUMIFS('Shopping List'!$G$2:$G$64,'Shopping List'!$A$2:$A$64,$A16,'Shopping List'!$H$2:$H$64,"<>Skip",'Shopping List'!$H$2:$H$64,"<>Got") -> 152.92 | C16: =SUMIFS('Shopping List'!$G$2:$G$64,'Shopping List'!$A$2:$A$64,$A16,'Shopping List'!$H$2:$H$64,"Want") -> 0 | D16: =SUMIFS('Shopping List'!$G$2:$G$64,'Shopping List'!$A$2:$A$64,$A16,'Shopping List'!$H$2:$H$64,"Got") -> 0 | E16: =COUNTIFS('Shopping List'!$A$2:$A$64,$A16) -> 7
A17: Bath & care | B17: =SUMIFS('Shopping List'!$G$2:$G$64,'Shopping List'!$A$2:$A$64,$A17,'Shopping List'!$H$2:$H$64,"<>Skip",'Shopping List'!$H$2:$H$64,"<>Got") -> 95.93 | C17: =SUMIFS('Shopping List'!$G$2:$G$64,'Shopping List'!$A$2:$A$64,$A17,'Shopping List'!$H$2:$H$64,"Want") -> 0 | D17: =SUMIFS('Shopping List'!$G$2:$G$64,'Shopping List'!$A$2:$A$64,$A17,'Shopping List'!$H$2:$H$64,"Got") -> 0 | E17: =COUNTIFS('Shopping List'!$A$2:$A$64,$A17) -> 5
A18: Health | B18: =SUMIFS('Shopping List'!$G$2:$G$64,'Shopping List'!$A$2:$A$64,$A18,'Shopping List'!$H$2:$H$64,"<>Skip",'Shopping List'!$H$2:$H$64,"<>Got") -> 43.77 | C18: =SUMIFS('Shopping List'!$G$2:$G$64,'Shopping List'!$A$2:$A$64,$A18,'Shopping List'!$H$2:$H$64,"Want") -> 0 | D18: =SUMIFS('Shopping List'!$G$2:$G$64,'Shopping List'!$A$2:$A$64,$A18,'Shopping List'!$H$2:$H$64,"Got") -> 0 | E18: =COUNTIFS('Shopping List'!$A$2:$A$64,$A18) -> 4
A19: Play | B19: =SUMIFS('Shopping List'!$G$2:$G$64,'Shopping List'!$A$2:$A$64,$A19,'Shopping List'!$H$2:$H$64,"<>Skip",'Shopping List'!$H$2:$H$64,"<>Got") -> 75.96 | C19: =SUMIFS('Shopping List'!$G$2:$G$64,'Shopping List'!$A$2:$A$64,$A19,'Shopping List'!$H$2:$H$64,"Want") -> 0 | D19: =SUMIFS('Shopping List'!$G$2:$G$64,'Shopping List'!$A$2:$A$64,$A19,'Shopping List'!$H$2:$H$64,"Got") -> 0 | E19: =COUNTIFS('Shopping List'!$A$2:$A$64,$A19) -> 2
A20: For mom | B20: =SUMIFS('Shopping List'!$G$2:$G$64,'Shopping List'!$A$2:$A$64,$A20,'Shopping List'!$H$2:$H$64,"<>Skip",'Shopping List'!$H$2:$H$64,"<>Got") -> 101.14 | C20: =SUMIFS('Shopping List'!$G$2:$G$64,'Shopping List'!$A$2:$A$64,$A20,'Shopping List'!$H$2:$H$64,"Want") -> 0 | D20: =SUMIFS('Shopping List'!$G$2:$G$64,'Shopping List'!$A$2:$A$64,$A20,'Shopping List'!$H$2:$H$64,"Got") -> 0 | E20: =COUNTIFS('Shopping List'!$A$2:$A$64,$A20) -> 6
A21: Hospital bag | B21: =SUMIFS('Shopping List'!$G$2:$G$64,'Shopping List'!$A$2:$A$64,$A21,'Shopping List'!$H$2:$H$64,"<>Skip",'Shopping List'!$H$2:$H$64,"<>Got") -> 9.99 | C21: =SUMIFS('Shopping List'!$G$2:$G$64,'Shopping List'!$A$2:$A$64,$A21,'Shopping List'!$H$2:$H$64,"Want") -> 0 | D21: =SUMIFS('Shopping List'!$G$2:$G$64,'Shopping List'!$A$2:$A$64,$A21,'Shopping List'!$H$2:$H$64,"Got") -> 0 | E21: =COUNTIFS('Shopping List'!$A$2:$A$64,$A21) -> 4
A23: How to use: on the Shopping List tab, set Status to Want, Got, or Skip, and change # to buy if needed (yellow cells). "Still to buy" leaves out Got and Skip items. Prices are from Amazon on Oct 9, 2026.

Sheet Tips
A1: Tips and money savers
A3: Amazon Baby Registry (private) | B3: Create a registry set to private and add these items. With Prime: a free welcome box (add 10 items and have $10 bought from it) and a 15% completion discount, up to $300, starting 60 days before the due date (about Dec 1). Source: amazon.com/baby-reg
A4: Breast pump through insurance | B4: Most plans must cover a breast pump. Services like Aeroflow (aeroflowbreastpumps.com) check coverage and ship one free. Start in December.
A5: Free car seat check | B5: Safe Kids Maricopa County runs free car seat checks. Install the seat by week 36 and have it checked.
A6: Newborn sizes | B6: Many babies outgrow newborn clothes and diapers in 2–4 weeks. Buy one pack of newborn diapers and focus on size 1 and 0–3 months.
A7: Hospital freebies | B7: Hospitals usually send you home with diapers, wipes, peri bottles, pads and mesh underwear. Take them.
A8: New vs used | B8: Buy car seats and crib mattresses new. Most other gear (bouncer, tub, clothes, play gym) is fine secondhand.
A9: February in Mesa | B9: Nights dip into the 40s. Use a sleep sack instead of loose blankets, and thin layers in the car seat, never a puffy coat under the straps.
A10: Safe sleep | B10: Baby sleeps on their back, alone, on a firm flat surface with only a fitted sheet. No bumpers, pillows, or loose blankets.
A11: Medicine | B11: Infant acetaminophen only with your pediatrician’s OK and dosing. A fever of 100.4°F or higher under 3 months old means calling the doctor right away.
